[2023-03-03 06:43:48] [INFO   ] discord.client: logging in using static token
[2023-03-03 06:43:59] [INFO   ] discord.client: logging in using static token
[2023-03-03 06:44:07] [INFO   ] discord.client: logging in using static token
[2023-03-03 06:44:39] [INFO   ] discord.client: logging in using static token
[2023-03-03 06:44:46] [INFO   ] discord.client: logging in using static token
[2023-03-03 06:44:53] [INFO   ] discord.client: logging in using static token
[2023-03-03 06:45:03] [INFO   ] discord.client: logging in using static token
[2023-03-03 06:45:10] [INFO   ] discord.client: logging in using static token
[2023-03-03 06:45:18] [INFO   ] discord.client: logging in using static token
[2023-03-03 06:46:32] [INFO   ] discord.client: logging in using static token
[2023-03-03 06:47:11] [INFO   ] discord.client: logging in using static token
[2023-03-03 06:48:13] [INFO   ] discord.client: logging in using static token
[2023-03-03 06:48:16] [INFO   ] discord.gateway: Shard ID 0 has connected to Gateway (Session ID: e13a62cffb326ee6f14a9edeac619988).
[2023-03-03 06:48:18] [INFO   ] bot: Ready: Uni ✨#4378 (ID: 924198727533600798)
[2023-03-03 06:48:18] [ERROR  ] discord.client: Ignoring exception in on_ready
Traceback (most recent call last):
  File "/home/runner/Uni-Python-Bot/venv/lib/python3.8/site-packages/discord/client.py", line 409, in _run_event
    await coro(*args, **kwargs)
  File "/home/runner/Uni-Python-Bot/cogs/Listeners.py", line 20, in on_ready
    util.uptime = datetime.now()
NameError: name 'util' is not defined
[2023-03-03 06:48:54] [INFO   ] discord.client: logging in using static token
[2023-03-03 06:48:56] [INFO   ] discord.gateway: Shard ID 0 has connected to Gateway (Session ID: cb379f1127e7035627696482fa34cf85).
[2023-03-03 06:48:58] [INFO   ] bot: Ready: Uni ✨#4378 (ID: 924198727533600798)
[2023-03-03 06:49:56] [ERROR  ] discord.client: Ignoring exception in on_message
Traceback (most recent call last):
  File "/home/runner/Uni-Python-Bot/venv/lib/python3.8/site-packages/discord/client.py", line 409, in _run_event
    await coro(*args, **kwargs)
  File "/home/runner/Uni-Python-Bot/cogs/Listeners.py", line 52, in on_message
    prefix = db.get(f"{message.guild.id}.prefix", "Guilds") or "?"
NameError: name 'db' is not defined
[2023-03-03 06:51:56] [ERROR  ] discord.client: Ignoring exception in on_message
Traceback (most recent call last):
  File "/home/runner/Uni-Python-Bot/venv/lib/python3.8/site-packages/discord/client.py", line 409, in _run_event
    await coro(*args, **kwargs)
  File "/home/runner/Uni-Python-Bot/cogs/Listeners.py", line 52, in on_message
    """
NameError: name 'db' is not defined
[2023-03-03 06:51:56] [ERROR  ] discord.client: Ignoring exception in on_command_error
Traceback (most recent call last):
  File "/home/runner/Uni-Python-Bot/venv/lib/python3.8/site-packages/discord/client.py", line 409, in _run_event
    await coro(*args, **kwargs)
  File "/home/runner/Uni-Python-Bot/cogs/Listeners.py", line 36, in on_command_error
    return await util.throw_error(ctx, "arg_not_found", error=True)
NameError: name 'util' is not defined
[2023-03-03 06:52:27] [ERROR  ] discord.client: Ignoring exception in on_message
Traceback (most recent call last):
  File "/home/runner/Uni-Python-Bot/venv/lib/python3.8/site-packages/discord/client.py", line 409, in _run_event
    await coro(*args, **kwargs)
  File "/home/runner/Uni-Python-Bot/cogs/Listeners.py", line 52, in on_message
    """
NameError: name 'db' is not defined
[2023-03-03 06:52:28] [ERROR  ] discord.client: Ignoring exception in on_command_error
Traceback (most recent call last):
  File "/home/runner/Uni-Python-Bot/venv/lib/python3.8/site-packages/discord/ext/commands/core.py", line 229, in wrapped
    ret = await coro(*args, **kwargs)
  File "/home/runner/Uni-Python-Bot/cogs/Configuration.py", line 18, in prefix
    embed = self.bot.util.Embed(ctx,
AttributeError: 'Util' object has no attribute 'Embed'

The above exception was the direct cause of the following exception:

Traceback (most recent call last):
  File "/home/runner/Uni-Python-Bot/venv/lib/python3.8/site-packages/discord/client.py", line 409, in _run_event
    await coro(*args, **kwargs)
  File "/home/runner/Uni-Python-Bot/cogs/Listeners.py", line 48, in on_command_error
    raise error
  File "/home/runner/Uni-Python-Bot/venv/lib/python3.8/site-packages/discord/ext/commands/bot.py", line 1349, in invoke
    await ctx.command.invoke(ctx)
  File "/home/runner/Uni-Python-Bot/venv/lib/python3.8/site-packages/discord/ext/commands/core.py", line 1647, in invoke
    await super().invoke(ctx)
  File "/home/runner/Uni-Python-Bot/venv/lib/python3.8/site-packages/discord/ext/commands/core.py", line 1023, in invoke
    await injected(*ctx.args, **ctx.kwargs)  # type: ignore
  File "/home/runner/Uni-Python-Bot/venv/lib/python3.8/site-packages/discord/ext/commands/core.py", line 238, in wrapped
    raise CommandInvokeError(exc) from exc
discord.ext.commands.errors.CommandInvokeError: Command raised an exception: AttributeError: 'Util' object has no attribute 'Embed'
[2023-03-03 06:53:34] [ERROR  ] discord.client: Ignoring exception in on_message
Traceback (most recent call last):
  File "/home/runner/Uni-Python-Bot/venv/lib/python3.8/site-packages/discord/client.py", line 409, in _run_event
    await coro(*args, **kwargs)
  File "/home/runner/Uni-Python-Bot/cogs/Listeners.py", line 52, in on_message
    """
NameError: name 'db' is not defined
[2023-03-03 06:55:18] [INFO   ] discord.client: logging in using static token
[2023-03-03 06:55:19] [INFO   ] discord.gateway: Shard ID 0 has connected to Gateway (Session ID: 7c988e64a943081e7d9407214b82ccc9).
[2023-03-03 06:55:22] [INFO   ] bot: Ready: Uni ✨#4378 (ID: 924198727533600798)
[2023-03-03 06:55:35] [ERROR  ] discord.client: Ignoring exception in on_command_error
Traceback (most recent call last):
  File "/home/runner/Uni-Python-Bot/venv/lib/python3.8/site-packages/discord/ext/commands/core.py", line 229, in wrapped
    ret = await coro(*args, **kwargs)
  File "/home/runner/Uni-Python-Bot/cogs/Configuration.py", line 18, in prefix
    embed = self.bot.util.Embed(ctx,
AttributeError: 'Util' object has no attribute 'Embed'

The above exception was the direct cause of the following exception:

Traceback (most recent call last):
  File "/home/runner/Uni-Python-Bot/venv/lib/python3.8/site-packages/discord/client.py", line 409, in _run_event
    await coro(*args, **kwargs)
  File "/home/runner/Uni-Python-Bot/cogs/Listeners.py", line 48, in on_command_error
    raise error
  File "/home/runner/Uni-Python-Bot/venv/lib/python3.8/site-packages/discord/ext/commands/bot.py", line 1349, in invoke
    await ctx.command.invoke(ctx)
  File "/home/runner/Uni-Python-Bot/venv/lib/python3.8/site-packages/discord/ext/commands/core.py", line 1647, in invoke
    await super().invoke(ctx)
  File "/home/runner/Uni-Python-Bot/venv/lib/python3.8/site-packages/discord/ext/commands/core.py", line 1023, in invoke
    await injected(*ctx.args, **ctx.kwargs)  # type: ignore
  File "/home/runner/Uni-Python-Bot/venv/lib/python3.8/site-packages/discord/ext/commands/core.py", line 238, in wrapped
    raise CommandInvokeError(exc) from exc
discord.ext.commands.errors.CommandInvokeError: Command raised an exception: AttributeError: 'Util' object has no attribute 'Embed'
[2023-03-03 06:59:34] [INFO   ] discord.client: logging in using static token
[2023-03-03 06:59:39] [INFO   ] discord.gateway: Shard ID 0 has connected to Gateway (Session ID: 189207bab0a42326993fc7ba985567a2).
[2023-03-03 06:59:42] [INFO   ] bot: Ready: Uni ✨#4378 (ID: 924198727533600798)
[2023-03-03 07:00:07] [INFO   ] discord.client: logging in using static token
[2023-03-03 07:00:10] [INFO   ] discord.gateway: Shard ID 0 has connected to Gateway (Session ID: 59ab415224d2b22ac3291071c6b6652d).
[2023-03-03 07:00:13] [INFO   ] bot: Ready: Uni ✨#4378 (ID: 924198727533600798)
[2023-03-03 07:00:31] [ERROR  ] discord.client: Ignoring exception in on_command_error
Traceback (most recent call last):
  File "/home/runner/Uni-Python-Bot/venv/lib/python3.8/site-packages/discord/ext/commands/core.py", line 229, in wrapped
    ret = await coro(*args, **kwargs)
  File "/home/runner/Uni-Python-Bot/cogs/Configuration.py", line 18, in prefix
    embed = self.bot.util.Embed(ctx,
AttributeError: 'Util' object has no attribute 'Embed'

The above exception was the direct cause of the following exception:

Traceback (most recent call last):
  File "/home/runner/Uni-Python-Bot/venv/lib/python3.8/site-packages/discord/client.py", line 409, in _run_event
    await coro(*args, **kwargs)
  File "/home/runner/Uni-Python-Bot/cogs/Listeners.py", line 48, in on_command_error
    raise error
  File "/home/runner/Uni-Python-Bot/venv/lib/python3.8/site-packages/discord/ext/commands/bot.py", line 1349, in invoke
    await ctx.command.invoke(ctx)
  File "/home/runner/Uni-Python-Bot/venv/lib/python3.8/site-packages/discord/ext/commands/core.py", line 1647, in invoke
    await super().invoke(ctx)
  File "/home/runner/Uni-Python-Bot/venv/lib/python3.8/site-packages/discord/ext/commands/core.py", line 1023, in invoke
    await injected(*ctx.args, **ctx.kwargs)  # type: ignore
  File "/home/runner/Uni-Python-Bot/venv/lib/python3.8/site-packages/discord/ext/commands/core.py", line 238, in wrapped
    raise CommandInvokeError(exc) from exc
discord.ext.commands.errors.CommandInvokeError: Command raised an exception: AttributeError: 'Util' object has no attribute 'Embed'
[2023-03-03 07:01:15] [INFO   ] discord.client: logging in using static token
[2023-03-03 07:01:24] [INFO   ] discord.gateway: Shard ID 0 has connected to Gateway (Session ID: 3f36b66369cd185670b15be171bec8e2).
[2023-03-03 07:01:26] [INFO   ] bot: Ready: Uni ✨#4378 (ID: 924198727533600798)
[2023-03-03 07:01:52] [ERROR  ] discord.client: Ignoring exception in on_command_error
Traceback (most recent call last):
  File "/home/runner/Uni-Python-Bot/venv/lib/python3.8/site-packages/discord/ext/commands/core.py", line 229, in wrapped
    ret = await coro(*args, **kwargs)
  File "/home/runner/Uni-Python-Bot/cogs/Configuration.py", line 18, in prefix
    embed = self.bot.util.Embed(ctx,
TypeError: Embed() takes 1 positional argument but 2 were given

The above exception was the direct cause of the following exception:

Traceback (most recent call last):
  File "/home/runner/Uni-Python-Bot/venv/lib/python3.8/site-packages/discord/client.py", line 409, in _run_event
    await coro(*args, **kwargs)
  File "/home/runner/Uni-Python-Bot/cogs/Listeners.py", line 48, in on_command_error
    raise error
  File "/home/runner/Uni-Python-Bot/venv/lib/python3.8/site-packages/discord/ext/commands/bot.py", line 1349, in invoke
    await ctx.command.invoke(ctx)
  File "/home/runner/Uni-Python-Bot/venv/lib/python3.8/site-packages/discord/ext/commands/core.py", line 1647, in invoke
    await super().invoke(ctx)
  File "/home/runner/Uni-Python-Bot/venv/lib/python3.8/site-packages/discord/ext/commands/core.py", line 1023, in invoke
    await injected(*ctx.args, **ctx.kwargs)  # type: ignore
  File "/home/runner/Uni-Python-Bot/venv/lib/python3.8/site-packages/discord/ext/commands/core.py", line 238, in wrapped
    raise CommandInvokeError(exc) from exc
discord.ext.commands.errors.CommandInvokeError: Command raised an exception: TypeError: Embed() takes 1 positional argument but 2 were given
[2023-03-03 07:02:15] [INFO   ] discord.client: logging in using static token
[2023-03-03 07:02:18] [INFO   ] discord.gateway: Shard ID 0 has connected to Gateway (Session ID: dbeb532225d49ae9cb8a4a3a12365c9a).
[2023-03-03 07:02:20] [INFO   ] bot: Ready: Uni ✨#4378 (ID: 924198727533600798)
[2023-03-03 07:04:17] [ERROR  ] discord.client: Ignoring exception in on_command_error
Traceback (most recent call last):
  File "/home/runner/Uni-Python-Bot/venv/lib/python3.8/site-packages/discord/ext/commands/core.py", line 229, in wrapped
    ret = await coro(*args, **kwargs)
  File "/home/runner/Uni-Python-Bot/cogs/Configuration.py", line 18, in prefix
    embed = self.bot.util.Embed(ctx,
  File "/home/runner/Uni-Python-Bot/util/Middleware.py", line 27, in Embed
    kwargs["footer"] = { "text": bot.config.footer, "icon_url": bot.config.footer_icon }
NameError: name 'bot' is not defined

The above exception was the direct cause of the following exception:

Traceback (most recent call last):
  File "/home/runner/Uni-Python-Bot/venv/lib/python3.8/site-packages/discord/client.py", line 409, in _run_event
    await coro(*args, **kwargs)
  File "/home/runner/Uni-Python-Bot/cogs/Listeners.py", line 48, in on_command_error
    raise error
  File "/home/runner/Uni-Python-Bot/venv/lib/python3.8/site-packages/discord/ext/commands/bot.py", line 1349, in invoke
    await ctx.command.invoke(ctx)
  File "/home/runner/Uni-Python-Bot/venv/lib/python3.8/site-packages/discord/ext/commands/core.py", line 1647, in invoke
    await super().invoke(ctx)
  File "/home/runner/Uni-Python-Bot/venv/lib/python3.8/site-packages/discord/ext/commands/core.py", line 1023, in invoke
    await injected(*ctx.args, **ctx.kwargs)  # type: ignore
  File "/home/runner/Uni-Python-Bot/venv/lib/python3.8/site-packages/discord/ext/commands/core.py", line 238, in wrapped
    raise CommandInvokeError(exc) from exc
discord.ext.commands.errors.CommandInvokeError: Command raised an exception: NameError: name 'bot' is not defined
[2023-03-03 07:05:17] [INFO   ] discord.client: logging in using static token
[2023-03-03 07:05:19] [INFO   ] discord.gateway: Shard ID 0 has connected to Gateway (Session ID: aa9350b24e10a24383f286e3848062cf).
[2023-03-03 07:05:21] [INFO   ] bot: Ready: Uni ✨#4378 (ID: 924198727533600798)
[2023-03-03 07:07:03] [ERROR  ] discord.client: Ignoring exception in on_command_error
Traceback (most recent call last):
  File "/home/runner/Uni-Python-Bot/venv/lib/python3.8/site-packages/discord/ext/commands/core.py", line 229, in wrapped
    ret = await coro(*args, **kwargs)
  File "/home/runner/Uni-Python-Bot/cogs/Configuration.py", line 18, in prefix
    embed = self.bot.util.Embed(ctx,
  File "/home/runner/Uni-Python-Bot/util/Middleware.py", line 31, in Embed
    embed = discord.Embed().from_dict(kwargs)
  File "/home/runner/Uni-Python-Bot/venv/lib/python3.8/site-packages/discord/embeds.py", line 236, in from_dict
    self._timestamp = utils.parse_time(data['timestamp'])
  File "/home/runner/Uni-Python-Bot/venv/lib/python3.8/site-packages/discord/utils.py", line 278, in parse_time
    return datetime.datetime.fromisoformat(timestamp)
TypeError: fromisoformat: argument must be str

The above exception was the direct cause of the following exception:

Traceback (most recent call last):
  File "/home/runner/Uni-Python-Bot/venv/lib/python3.8/site-packages/discord/client.py", line 409, in _run_event
    await coro(*args, **kwargs)
  File "/home/runner/Uni-Python-Bot/cogs/Listeners.py", line 48, in on_command_error
    raise error
  File "/home/runner/Uni-Python-Bot/venv/lib/python3.8/site-packages/discord/ext/commands/bot.py", line 1349, in invoke
    await ctx.command.invoke(ctx)
  File "/home/runner/Uni-Python-Bot/venv/lib/python3.8/site-packages/discord/ext/commands/core.py", line 1647, in invoke
    await super().invoke(ctx)
  File "/home/runner/Uni-Python-Bot/venv/lib/python3.8/site-packages/discord/ext/commands/core.py", line 1023, in invoke
    await injected(*ctx.args, **ctx.kwargs)  # type: ignore
  File "/home/runner/Uni-Python-Bot/venv/lib/python3.8/site-packages/discord/ext/commands/core.py", line 238, in wrapped
    raise CommandInvokeError(exc) from exc
discord.ext.commands.errors.CommandInvokeError: Command raised an exception: TypeError: fromisoformat: argument must be str
[2023-03-03 07:10:41] [INFO   ] discord.client: logging in using static token
[2023-03-03 07:10:43] [INFO   ] discord.gateway: Shard ID 0 has connected to Gateway (Session ID: 275bc03d0ab76036e6aa3ba95fc18ae8).
[2023-03-03 07:10:46] [INFO   ] bot: Ready: Uni ✨#4378 (ID: 924198727533600798)
[2023-03-03 07:10:48] [ERROR  ] discord.client: Ignoring exception in on_command_error
Traceback (most recent call last):
  File "/home/runner/Uni-Python-Bot/venv/lib/python3.8/site-packages/discord/ext/commands/core.py", line 229, in wrapped
    ret = await coro(*args, **kwargs)
  File "/home/runner/Uni-Python-Bot/cogs/Configuration.py", line 18, in prefix
    embed = self.bot.util.Embed(ctx,
  File "/home/runner/Uni-Python-Bot/util/Middleware.py", line 31, in Embed
    embed = discord.Embed().from_dict(kwargs)
  File "/home/runner/Uni-Python-Bot/venv/lib/python3.8/site-packages/discord/embeds.py", line 236, in from_dict
    self._timestamp = utils.parse_time(data['timestamp'])
  File "/home/runner/Uni-Python-Bot/venv/lib/python3.8/site-packages/discord/utils.py", line 278, in parse_time
    return datetime.datetime.fromisoformat(timestamp)
TypeError: fromisoformat: argument must be str

The above exception was the direct cause of the following exception:

Traceback (most recent call last):
  File "/home/runner/Uni-Python-Bot/venv/lib/python3.8/site-packages/discord/client.py", line 409, in _run_event
    await coro(*args, **kwargs)
  File "/home/runner/Uni-Python-Bot/cogs/Listeners.py", line 48, in on_command_error
    raise error
  File "/home/runner/Uni-Python-Bot/venv/lib/python3.8/site-packages/discord/ext/commands/bot.py", line 1349, in invoke
    await ctx.command.invoke(ctx)
  File "/home/runner/Uni-Python-Bot/venv/lib/python3.8/site-packages/discord/ext/commands/core.py", line 1647, in invoke
    await super().invoke(ctx)
  File "/home/runner/Uni-Python-Bot/venv/lib/python3.8/site-packages/discord/ext/commands/core.py", line 1023, in invoke
    await injected(*ctx.args, **ctx.kwargs)  # type: ignore
  File "/home/runner/Uni-Python-Bot/venv/lib/python3.8/site-packages/discord/ext/commands/core.py", line 238, in wrapped
    raise CommandInvokeError(exc) from exc
discord.ext.commands.errors.CommandInvokeError: Command raised an exception: TypeError: fromisoformat: argument must be str
[2023-03-03 07:17:03] [INFO   ] discord.client: logging in using static token
[2023-03-03 07:17:05] [INFO   ] discord.gateway: Shard ID 0 has connected to Gateway (Session ID: 11bd1bf6b62ed3baf5bacf625557ba10).
[2023-03-03 07:17:07] [ERROR  ] discord.client: Ignoring exception in on_command_error
Traceback (most recent call last):
  File "/home/runner/Uni-Python-Bot/venv/lib/python3.8/site-packages/discord/ext/commands/core.py", line 229, in wrapped
    ret = await coro(*args, **kwargs)
  File "/home/runner/Uni-Python-Bot/cogs/Configuration.py", line 18, in prefix
    embed = self.bot.util.Embed(ctx,
  File "/home/runner/Uni-Python-Bot/util/Middleware.py", line 31, in Embed
    embed = discord.Embed().from_dict(kwargs)
  File "/home/runner/Uni-Python-Bot/venv/lib/python3.8/site-packages/discord/embeds.py", line 236, in from_dict
    self._timestamp = utils.parse_time(data['timestamp'])
  File "/home/runner/Uni-Python-Bot/venv/lib/python3.8/site-packages/discord/utils.py", line 278, in parse_time
    return datetime.datetime.fromisoformat(timestamp)
TypeError: fromisoformat: argument must be str

The above exception was the direct cause of the following exception:

Traceback (most recent call last):
  File "/home/runner/Uni-Python-Bot/venv/lib/python3.8/site-packages/discord/client.py", line 409, in _run_event
    await coro(*args, **kwargs)
  File "/home/runner/Uni-Python-Bot/cogs/Listeners.py", line 48, in on_command_error
    raise error
  File "/home/runner/Uni-Python-Bot/venv/lib/python3.8/site-packages/discord/ext/commands/bot.py", line 1349, in invoke
    await ctx.command.invoke(ctx)
  File "/home/runner/Uni-Python-Bot/venv/lib/python3.8/site-packages/discord/ext/commands/core.py", line 1647, in invoke
    await super().invoke(ctx)
  File "/home/runner/Uni-Python-Bot/venv/lib/python3.8/site-packages/discord/ext/commands/core.py", line 1023, in invoke
    await injected(*ctx.args, **ctx.kwargs)  # type: ignore
  File "/home/runner/Uni-Python-Bot/venv/lib/python3.8/site-packages/discord/ext/commands/core.py", line 238, in wrapped
    raise CommandInvokeError(exc) from exc
discord.ext.commands.errors.CommandInvokeError: Command raised an exception: TypeError: fromisoformat: argument must be str
[2023-03-03 07:17:08] [INFO   ] bot: Ready: Uni ✨#4378 (ID: 924198727533600798)
[2023-03-03 07:21:54] [INFO   ] discord.client: logging in using static token
[2023-03-03 07:21:56] [INFO   ] discord.gateway: Shard ID 0 has connected to Gateway (Session ID: 925682a3dcd838a48aecf371614c36ec).
[2023-03-03 07:21:58] [INFO   ] bot: Ready: Uni ✨#4378 (ID: 924198727533600798)
[2023-03-03 07:30:02] [INFO   ] discord.client: logging in using static token
[2023-03-03 07:30:03] [INFO   ] discord.gateway: Shard ID 0 has connected to Gateway (Session ID: dd1472c524e3ae671d8ec435ea33bd82).
[2023-03-03 07:30:05] [INFO   ] bot: Ready: Uni ✨#4378 (ID: 924198727533600798)
[2023-03-03 07:30:05] [ERROR  ] discord.client: Ignoring exception in on_ready
Traceback (most recent call last):
  File "/home/runner/Uni-Python-Bot/venv/lib/python3.8/site-packages/discord/client.py", line 409, in _run_event
    await coro(*args, **kwargs)
  File "/home/runner/Uni-Python-Bot/cogs/Listeners.py", line 15, in on_ready
    Locales.fetch_langs(self.bot)
  File "/home/runner/Uni-Python-Bot/util/Locales.py", line 20, in fetch_langs
    for cmd in list(cog.walk_commands):
TypeError: 'method' object is not iterable
[2023-03-03 07:40:14] [INFO   ] discord.client: logging in using static token
[2023-03-03 07:40:57] [INFO   ] discord.client: logging in using static token
[2023-03-03 07:40:59] [INFO   ] discord.gateway: Shard ID 0 has connected to Gateway (Session ID: 6d1cafe358eedfc0796b3c52eedc4881).
[2023-03-03 07:41:01] [INFO   ] bot: Ready: Uni ✨#4378 (ID: 924198727533600798)
[2023-03-03 07:41:01] [ERROR  ] discord.client: Ignoring exception in on_ready
Traceback (most recent call last):
  File "/home/runner/Uni-Python-Bot/venv/lib/python3.8/site-packages/discord/client.py", line 409, in _run_event
    await coro(*args, **kwargs)
  File "/home/runner/Uni-Python-Bot/cogs/Listeners.py", line 15, in on_ready
    Locales.fetch_langs(self.bot)
  File "/home/runner/Uni-Python-Bot/util/Locales.py", line 18, in fetch_langs
    for cmd in list(cog.walk_commands):
TypeError: 'method' object is not iterable
[2023-03-03 07:42:48] [INFO   ] discord.client: logging in using static token
[2023-03-03 07:42:49] [INFO   ] discord.gateway: Shard ID 0 has connected to Gateway (Session ID: 88b994ae1405768fa8790752c3dc3226).
[2023-03-03 07:42:52] [INFO   ] bot: Ready: Uni ✨#4378 (ID: 924198727533600798)
[2023-03-03 07:43:03] [INFO   ] discord.client: logging in using static token
[2023-03-03 07:43:04] [INFO   ] discord.gateway: Shard ID 0 has connected to Gateway (Session ID: 21bffad735364fc6360f14412b45b05b).
[2023-03-03 07:43:06] [INFO   ] bot: Ready: Uni ✨#4378 (ID: 924198727533600798)
[2023-03-03 07:43:42] [ERROR  ] discord.client: Ignoring exception in on_command_error
Traceback (most recent call last):
  File "/home/runner/Uni-Python-Bot/venv/lib/python3.8/site-packages/discord/ext/commands/core.py", line 229, in wrapped
    ret = await coro(*args, **kwargs)
  File "/home/runner/Uni-Python-Bot/cogs/Configuration.py", line 42, in p_add
    await Locales.send_fine(ctx, "Configuration", "prefix_add", "fine_message", prefix=prefix)
AttributeError: module 'util.Locales' has no attribute 'send_fine'

The above exception was the direct cause of the following exception:

Traceback (most recent call last):
  File "/home/runner/Uni-Python-Bot/venv/lib/python3.8/site-packages/discord/client.py", line 409, in _run_event
    await coro(*args, **kwargs)
  File "/home/runner/Uni-Python-Bot/cogs/Listeners.py", line 48, in on_command_error
    raise error
  File "/home/runner/Uni-Python-Bot/venv/lib/python3.8/site-packages/discord/ext/commands/bot.py", line 1349, in invoke
    await ctx.command.invoke(ctx)
  File "/home/runner/Uni-Python-Bot/venv/lib/python3.8/site-packages/discord/ext/commands/core.py", line 1642, in invoke
    await ctx.invoked_subcommand.invoke(ctx)
  File "/home/runner/Uni-Python-Bot/venv/lib/python3.8/site-packages/discord/ext/commands/core.py", line 1023, in invoke
    await injected(*ctx.args, **ctx.kwargs)  # type: ignore
  File "/home/runner/Uni-Python-Bot/venv/lib/python3.8/site-packages/discord/ext/commands/core.py", line 238, in wrapped
    raise CommandInvokeError(exc) from exc
discord.ext.commands.errors.CommandInvokeError: Command raised an exception: AttributeError: module 'util.Locales' has no attribute 'send_fine'
[2023-03-03 07:44:00] [ERROR  ] discord.client: Ignoring exception in on_command_error
Traceback (most recent call last):
  File "/home/runner/Uni-Python-Bot/venv/lib/python3.8/site-packages/discord/ext/commands/core.py", line 229, in wrapped
    ret = await coro(*args, **kwargs)
  File "/home/runner/Uni-Python-Bot/cogs/Configuration.py", line 36, in p_add
    return await Locales.send_error(ctx, "Configuration", "prefix_add", "length_limit", prefix=prefix)
TypeError: send_error() missing 1 required positional argument: 'key'

The above exception was the direct cause of the following exception:

Traceback (most recent call last):
  File "/home/runner/Uni-Python-Bot/venv/lib/python3.8/site-packages/discord/client.py", line 409, in _run_event
    await coro(*args, **kwargs)
  File "/home/runner/Uni-Python-Bot/cogs/Listeners.py", line 48, in on_command_error
    raise error
  File "/home/runner/Uni-Python-Bot/venv/lib/python3.8/site-packages/discord/ext/commands/bot.py", line 1349, in invoke
    await ctx.command.invoke(ctx)
  File "/home/runner/Uni-Python-Bot/venv/lib/python3.8/site-packages/discord/ext/commands/core.py", line 1642, in invoke
    await ctx.invoked_subcommand.invoke(ctx)
  File "/home/runner/Uni-Python-Bot/venv/lib/python3.8/site-packages/discord/ext/commands/core.py", line 1023, in invoke
    await injected(*ctx.args, **ctx.kwargs)  # type: ignore
  File "/home/runner/Uni-Python-Bot/venv/lib/python3.8/site-packages/discord/ext/commands/core.py", line 238, in wrapped
    raise CommandInvokeError(exc) from exc
discord.ext.commands.errors.CommandInvokeError: Command raised an exception: TypeError: send_error() missing 1 required positional argument: 'key'
[2023-03-03 07:45:17] [INFO   ] discord.client: logging in using static token
[2023-03-03 07:45:19] [INFO   ] discord.gateway: Shard ID 0 has connected to Gateway (Session ID: 8dc3c3d8a19e2bc4e3b24ab3a11d13a2).
[2023-03-03 07:45:21] [INFO   ] bot: Ready: Uni ✨#4378 (ID: 924198727533600798)
[2023-03-03 07:45:33] [ERROR  ] discord.client: Ignoring exception in on_command_error
Traceback (most recent call last):
  File "/home/runner/Uni-Python-Bot/venv/lib/python3.8/site-packages/discord/ext/commands/core.py", line 229, in wrapped
    ret = await coro(*args, **kwargs)
  File "/home/runner/Uni-Python-Bot/cogs/Configuration.py", line 42, in p_add
    await Locales.send_fine(ctx, "Configuration", "prefix_add", "fine_message", prefix=prefix)
AttributeError: module 'util.Locales' has no attribute 'send_fine'

The above exception was the direct cause of the following exception:

Traceback (most recent call last):
  File "/home/runner/Uni-Python-Bot/venv/lib/python3.8/site-packages/discord/client.py", line 409, in _run_event
    await coro(*args, **kwargs)
  File "/home/runner/Uni-Python-Bot/cogs/Listeners.py", line 48, in on_command_error
    raise error
  File "/home/runner/Uni-Python-Bot/venv/lib/python3.8/site-packages/discord/ext/commands/bot.py", line 1349, in invoke
    await ctx.command.invoke(ctx)
  File "/home/runner/Uni-Python-Bot/venv/lib/python3.8/site-packages/discord/ext/commands/core.py", line 1642, in invoke
    await ctx.invoked_subcommand.invoke(ctx)
  File "/home/runner/Uni-Python-Bot/venv/lib/python3.8/site-packages/discord/ext/commands/core.py", line 1023, in invoke
    await injected(*ctx.args, **ctx.kwargs)  # type: ignore
  File "/home/runner/Uni-Python-Bot/venv/lib/python3.8/site-packages/discord/ext/commands/core.py", line 238, in wrapped
    raise CommandInvokeError(exc) from exc
discord.ext.commands.errors.CommandInvokeError: Command raised an exception: AttributeError: module 'util.Locales' has no attribute 'send_fine'
[2023-03-03 07:46:06] [INFO   ] discord.client: logging in using static token
[2023-03-03 07:46:07] [INFO   ] discord.gateway: Shard ID 0 has connected to Gateway (Session ID: 0ddb880fe5409ed42ecd8bd1ff04dea1).
[2023-03-03 07:46:10] [INFO   ] bot: Ready: Uni ✨#4378 (ID: 924198727533600798)
[2023-03-03 07:50:30] [INFO   ] discord.client: logging in using static token
[2023-03-03 07:50:31] [INFO   ] discord.gateway: Shard ID 0 has connected to Gateway (Session ID: fd8f93fcac30a649a48f900a8296041b).
[2023-03-03 07:50:33] [INFO   ] bot: Ready: Uni ✨#4378 (ID: 924198727533600798)
[2023-03-03 07:51:32] [ERROR  ] discord.client: Ignoring exception in on_message
Traceback (most recent call last):
  File "/home/runner/Uni-Python-Bot/venv/lib/python3.8/site-packages/discord/client.py", line 409, in _run_event
    await coro(*args, **kwargs)
  File "/home/runner/Uni-Python-Bot/bot.py", line 186, in on_message
    await self.process_commands(message)
  File "/home/runner/Uni-Python-Bot/bot.py", line 156, in process_commands
    ctx = await self.get_context(message)
  File "/home/runner/Uni-Python-Bot/bot.py", line 153, in get_context
    return await super().get_context(origin, cls=cls)
  File "/home/runner/Uni-Python-Bot/venv/lib/python3.8/site-packages/discord/ext/commands/bot.py", line 1288, in get_context
    prefix = await self.get_prefix(origin)
  File "/home/runner/Uni-Python-Bot/venv/lib/python3.8/site-packages/discord/ext/commands/bot.py", line 1195, in get_prefix
    ret = await discord.utils.maybe_coroutine(prefix, self, message)  # type: ignore
  File "/home/runner/Uni-Python-Bot/venv/lib/python3.8/site-packages/discord/utils.py", line 662, in maybe_coroutine
    return await value
  File "/home/runner/Uni-Python-Bot/bot.py", line 38, in _prefix
    message.guild.id, [config.prefix], "en"
AttributeError: module 'config' has no attribute 'prefix'
[2023-03-03 07:52:01] [ERROR  ] discord.client: Ignoring exception in on_message
Traceback (most recent call last):
  File "/home/runner/Uni-Python-Bot/venv/lib/python3.8/site-packages/discord/client.py", line 409, in _run_event
    await coro(*args, **kwargs)
  File "/home/runner/Uni-Python-Bot/bot.py", line 186, in on_message
    await self.process_commands(message)
  File "/home/runner/Uni-Python-Bot/bot.py", line 156, in process_commands
    ctx = await self.get_context(message)
  File "/home/runner/Uni-Python-Bot/bot.py", line 153, in get_context
    return await super().get_context(origin, cls=cls)
  File "/home/runner/Uni-Python-Bot/venv/lib/python3.8/site-packages/discord/ext/commands/bot.py", line 1288, in get_context
    prefix = await self.get_prefix(origin)
  File "/home/runner/Uni-Python-Bot/venv/lib/python3.8/site-packages/discord/ext/commands/bot.py", line 1195, in get_prefix
    ret = await discord.utils.maybe_coroutine(prefix, self, message)  # type: ignore
  File "/home/runner/Uni-Python-Bot/venv/lib/python3.8/site-packages/discord/utils.py", line 662, in maybe_coroutine
    return await value
  File "/home/runner/Uni-Python-Bot/bot.py", line 38, in _prefix
    message.guild.id, [config.prefix], "en"
AttributeError: module 'config' has no attribute 'prefix'
[2023-03-03 07:53:28] [INFO   ] discord.client: logging in using static token
[2023-03-03 07:53:29] [INFO   ] discord.gateway: Shard ID 0 has connected to Gateway (Session ID: ba21e1d334a0ba461efca0fc3f90ffe4).
[2023-03-03 07:53:31] [INFO   ] bot: Ready: Uni ✨#4378 (ID: 924198727533600798)
[2023-03-03 07:55:47] [INFO   ] discord.client: logging in using static token
[2023-03-03 07:55:49] [INFO   ] discord.gateway: Shard ID 0 has connected to Gateway (Session ID: a7b8d23c985ebd346057f7a13e62825d).
[2023-03-03 07:55:51] [INFO   ] bot: Ready: Uni ✨#4378 (ID: 924198727533600798)
[2023-03-03 08:00:38] [INFO   ] discord.client: logging in using static token
[2023-03-03 08:00:41] [INFO   ] discord.gateway: Shard ID 0 has connected to Gateway (Session ID: b8e18218f5760a37dff489c356702150).
[2023-03-03 08:00:43] [INFO   ] bot: Ready: Uni ✨#4378 (ID: 924198727533600798)
[2023-03-03 08:04:26] [INFO   ] discord.client: logging in using static token
[2023-03-03 08:04:27] [INFO   ] discord.gateway: Shard ID 0 has connected to Gateway (Session ID: b8ba223feeab3fec218aaeb28ebf04a7).
[2023-03-03 08:04:29] [INFO   ] bot: Ready: Uni ✨#4378 (ID: 924198727533600798)
[2023-03-03 08:05:36] [INFO   ] discord.client: logging in using static token
[2023-03-03 08:05:37] [INFO   ] discord.gateway: Shard ID 0 has connected to Gateway (Session ID: 64e9497b129c857fdd4b67d9000e52d7).
[2023-03-03 08:05:39] [INFO   ] bot: Ready: Uni ✨#4378 (ID: 924198727533600798)
[2023-03-03 08:05:55] [ERROR  ] discord.client: Ignoring exception in on_command_error
Traceback (most recent call last):
  File "/home/runner/Uni-Python-Bot/venv/lib/python3.8/site-packages/discord/ext/commands/core.py", line 229, in wrapped
    ret = await coro(*args, **kwargs)
  File "/home/runner/Uni-Python-Bot/cogs/Configuration.py", line 36, in p_add
    return await Locales.send(ctx, "Configuration", "prefix_add", "length_limit", like="error", prefix=prefix)
TypeError: send() got multiple values for argument 'like'

The above exception was the direct cause of the following exception:

Traceback (most recent call last):
  File "/home/runner/Uni-Python-Bot/venv/lib/python3.8/site-packages/discord/client.py", line 409, in _run_event
    await coro(*args, **kwargs)
  File "/home/runner/Uni-Python-Bot/cogs/Listeners.py", line 48, in on_command_error
    raise error
  File "/home/runner/Uni-Python-Bot/venv/lib/python3.8/site-packages/discord/ext/commands/bot.py", line 1349, in invoke
    await ctx.command.invoke(ctx)
  File "/home/runner/Uni-Python-Bot/venv/lib/python3.8/site-packages/discord/ext/commands/core.py", line 1642, in invoke
    await ctx.invoked_subcommand.invoke(ctx)
  File "/home/runner/Uni-Python-Bot/venv/lib/python3.8/site-packages/discord/ext/commands/core.py", line 1023, in invoke
    await injected(*ctx.args, **ctx.kwargs)  # type: ignore
  File "/home/runner/Uni-Python-Bot/venv/lib/python3.8/site-packages/discord/ext/commands/core.py", line 238, in wrapped
    raise CommandInvokeError(exc) from exc
discord.ext.commands.errors.CommandInvokeError: Command raised an exception: TypeError: send() got multiple values for argument 'like'
[2023-03-03 08:06:42] [INFO   ] discord.client: logging in using static token
[2023-03-03 08:06:44] [INFO   ] discord.gateway: Shard ID 0 has connected to Gateway (Session ID: cc75be209cc625ee90e05a96f70923b0).
[2023-03-03 08:06:46] [INFO   ] bot: Ready: Uni ✨#4378 (ID: 924198727533600798)
[2023-03-03 08:06:55] [ERROR  ] discord.client: Ignoring exception in on_command_error
Traceback (most recent call last):
  File "/home/runner/Uni-Python-Bot/venv/lib/python3.8/site-packages/discord/ext/commands/core.py", line 229, in wrapped
    ret = await coro(*args, **kwargs)
  File "/home/runner/Uni-Python-Bot/cogs/Configuration.py", line 36, in p_add
    return await Locales.send(ctx, "Configuration", "prefix_add", "length_limit", like="error", prefix=prefix)
TypeError: send() takes 3 positional arguments but 4 positional arguments (and 1 keyword-only argument) were given

The above exception was the direct cause of the following exception:

Traceback (most recent call last):
  File "/home/runner/Uni-Python-Bot/venv/lib/python3.8/site-packages/discord/client.py", line 409, in _run_event
    await coro(*args, **kwargs)
  File "/home/runner/Uni-Python-Bot/cogs/Listeners.py", line 48, in on_command_error
    raise error
  File "/home/runner/Uni-Python-Bot/venv/lib/python3.8/site-packages/discord/ext/commands/bot.py", line 1349, in invoke
    await ctx.command.invoke(ctx)
  File "/home/runner/Uni-Python-Bot/venv/lib/python3.8/site-packages/discord/ext/commands/core.py", line 1642, in invoke
    await ctx.invoked_subcommand.invoke(ctx)
  File "/home/runner/Uni-Python-Bot/venv/lib/python3.8/site-packages/discord/ext/commands/core.py", line 1023, in invoke
    await injected(*ctx.args, **ctx.kwargs)  # type: ignore
  File "/home/runner/Uni-Python-Bot/venv/lib/python3.8/site-packages/discord/ext/commands/core.py", line 238, in wrapped
    raise CommandInvokeError(exc) from exc
discord.ext.commands.errors.CommandInvokeError: Command raised an exception: TypeError: send() takes 3 positional arguments but 4 positional arguments (and 1 keyword-only argument) were given
[2023-03-03 08:06:56] [ERROR  ] discord.client: Ignoring exception in on_command_error
Traceback (most recent call last):
  File "/home/runner/Uni-Python-Bot/venv/lib/python3.8/site-packages/discord/ext/commands/core.py", line 229, in wrapped
    ret = await coro(*args, **kwargs)
  File "/home/runner/Uni-Python-Bot/cogs/Configuration.py", line 36, in p_add
    return await Locales.send(ctx, "Configuration", "prefix_add", "length_limit", like="error", prefix=prefix)
TypeError: send() takes 3 positional arguments but 4 positional arguments (and 1 keyword-only argument) were given

The above exception was the direct cause of the following exception:

Traceback (most recent call last):
  File "/home/runner/Uni-Python-Bot/venv/lib/python3.8/site-packages/discord/client.py", line 409, in _run_event
    await coro(*args, **kwargs)
  File "/home/runner/Uni-Python-Bot/cogs/Listeners.py", line 48, in on_command_error
    raise error
  File "/home/runner/Uni-Python-Bot/venv/lib/python3.8/site-packages/discord/ext/commands/bot.py", line 1349, in invoke
    await ctx.command.invoke(ctx)
  File "/home/runner/Uni-Python-Bot/venv/lib/python3.8/site-packages/discord/ext/commands/core.py", line 1642, in invoke
    await ctx.invoked_subcommand.invoke(ctx)
  File "/home/runner/Uni-Python-Bot/venv/lib/python3.8/site-packages/discord/ext/commands/core.py", line 1023, in invoke
    await injected(*ctx.args, **ctx.kwargs)  # type: ignore
  File "/home/runner/Uni-Python-Bot/venv/lib/python3.8/site-packages/discord/ext/commands/core.py", line 238, in wrapped
    raise CommandInvokeError(exc) from exc
discord.ext.commands.errors.CommandInvokeError: Command raised an exception: TypeError: send() takes 3 positional arguments but 4 positional arguments (and 1 keyword-only argument) were given
[2023-03-03 08:07:22] [INFO   ] discord.client: logging in using static token
[2023-03-03 08:07:31] [INFO   ] discord.client: logging in using static token
[2023-03-03 08:08:34] [INFO   ] discord.client: logging in using static token
[2023-03-03 08:08:36] [INFO   ] discord.gateway: Shard ID 0 has connected to Gateway (Session ID: 4f8a01b7dc8792d9cdcfc7388fe8c400).
[2023-03-03 08:08:38] [INFO   ] bot: Ready: Uni ✨#4378 (ID: 924198727533600798)
[2023-03-03 08:10:44] [INFO   ] discord.client: logging in using static token
[2023-03-03 08:10:45] [INFO   ] discord.gateway: Shard ID 0 has connected to Gateway (Session ID: 66e30b7df6bec55320c9c76105587c3d).
[2023-03-03 08:10:47] [INFO   ] bot: Ready: Uni ✨#4378 (ID: 924198727533600798)
[2023-03-03 15:40:46] [INFO   ] discord.client: logging in using static token
[2023-03-03 15:40:50] [INFO   ] discord.gateway: Shard ID 0 has connected to Gateway (Session ID: b90790f878d10c907a263b74567ec64c).
[2023-03-03 15:40:52] [INFO   ] bot: Ready: Uni ✨#4378 (ID: 924198727533600798)
[2023-03-03 16:41:09] [INFO   ] discord.client: logging in using static token
[2023-03-03 16:41:13] [INFO   ] discord.gateway: Shard ID 0 has connected to Gateway (Session ID: eaac98a96c3a6c7324d9323bf49768b0).
[2023-03-03 16:41:15] [INFO   ] bot: Ready: Uni ✨#4378 (ID: 924198727533600798)
[2023-03-03 17:28:04] [INFO   ] discord.client: logging in using static token
[2023-03-03 17:28:08] [INFO   ] discord.gateway: Shard ID 0 has connected to Gateway (Session ID: 35edb6b5639c61e7a08fc48d2325de8c).
[2023-03-03 17:28:10] [INFO   ] bot: Ready: Uni ✨#4378 (ID: 924198727533600798)
[2023-03-03 18:09:27] [INFO   ] discord.client: logging in using static token
[2023-03-03 18:09:30] [INFO   ] discord.gateway: Shard ID 0 has connected to Gateway (Session ID: 9557a916595d6bddced2cf94ce27f2d9).
[2023-03-03 18:09:33] [INFO   ] bot: Ready: Uni ✨#4378 (ID: 924198727533600798)
[2023-03-03 18:54:44] [INFO   ] discord.client: logging in using static token
[2023-03-03 18:54:47] [INFO   ] discord.gateway: Shard ID 0 has connected to Gateway (Session ID: 9b65ed3cfee816dac895bcabbf0d1b65).
[2023-03-03 18:54:50] [INFO   ] bot: Ready: Uni ✨#4378 (ID: 924198727533600798)
[2023-03-03 18:55:26] [ERROR  ] discord.client: Ignoring exception in on_command_error
Traceback (most recent call last):
  File "/home/runner/Uni-Python-Bot/venv/lib/python3.8/site-packages/discord/ext/commands/core.py", line 229, in wrapped
    ret = await coro(*args, **kwargs)
  File "/home/runner/Uni-Python-Bot/cogs/Information.py", line 15, in user
    await self.info(ctx, user)
  File "/home/runner/Uni-Python-Bot/venv/lib/python3.8/site-packages/discord/ext/commands/core.py", line 582, in __call__
    return await self.callback(self.cog, context, *args, **kwargs)  # type: ignore
  File "/home/runner/Uni-Python-Bot/cogs/Information.py", line 23, in info
    title=Locales.get(ctx, "embed_title", cmd="info"),
NameError: name 'Locales' is not defined

The above exception was the direct cause of the following exception:

Traceback (most recent call last):
  File "/home/runner/Uni-Python-Bot/venv/lib/python3.8/site-packages/discord/client.py", line 409, in _run_event
    await coro(*args, **kwargs)
  File "/home/runner/Uni-Python-Bot/cogs/Listeners.py", line 40, in on_command_error
    raise error
  File "/home/runner/Uni-Python-Bot/venv/lib/python3.8/site-packages/discord/ext/commands/bot.py", line 1349, in invoke
    await ctx.command.invoke(ctx)
  File "/home/runner/Uni-Python-Bot/venv/lib/python3.8/site-packages/discord/ext/commands/core.py", line 1647, in invoke
    await super().invoke(ctx)
  File "/home/runner/Uni-Python-Bot/venv/lib/python3.8/site-packages/discord/ext/commands/core.py", line 1023, in invoke
    await injected(*ctx.args, **ctx.kwargs)  # type: ignore
  File "/home/runner/Uni-Python-Bot/venv/lib/python3.8/site-packages/discord/ext/commands/core.py", line 238, in wrapped
    raise CommandInvokeError(exc) from exc
discord.ext.commands.errors.CommandInvokeError: Command raised an exception: NameError: name 'Locales' is not defined
[2023-03-03 18:56:03] [ERROR  ] discord.client: Ignoring exception in on_command_error
Traceback (most recent call last):
  File "/home/runner/Uni-Python-Bot/venv/lib/python3.8/site-packages/discord/ext/commands/core.py", line 229, in wrapped
    ret = await coro(*args, **kwargs)
  File "/home/runner/Uni-Python-Bot/cogs/Information.py", line 23, in info
    title=Locales.get(ctx, "embed_title", cmd="info"),
NameError: name 'Locales' is not defined

The above exception was the direct cause of the following exception:

Traceback (most recent call last):
  File "/home/runner/Uni-Python-Bot/venv/lib/python3.8/site-packages/discord/client.py", line 409, in _run_event
    await coro(*args, **kwargs)
  File "/home/runner/Uni-Python-Bot/cogs/Listeners.py", line 40, in on_command_error
    raise error
  File "/home/runner/Uni-Python-Bot/venv/lib/python3.8/site-packages/discord/ext/commands/bot.py", line 1349, in invoke
    await ctx.command.invoke(ctx)
  File "/home/runner/Uni-Python-Bot/venv/lib/python3.8/site-packages/discord/ext/commands/core.py", line 1642, in invoke
    await ctx.invoked_subcommand.invoke(ctx)
  File "/home/runner/Uni-Python-Bot/venv/lib/python3.8/site-packages/discord/ext/commands/core.py", line 1023, in invoke
    await injected(*ctx.args, **ctx.kwargs)  # type: ignore
  File "/home/runner/Uni-Python-Bot/venv/lib/python3.8/site-packages/discord/ext/commands/core.py", line 238, in wrapped
    raise CommandInvokeError(exc) from exc
discord.ext.commands.errors.CommandInvokeError: Command raised an exception: NameError: name 'Locales' is not defined
[2023-03-03 18:57:30] [INFO   ] discord.client: logging in using static token
[2023-03-03 18:57:44] [INFO   ] discord.client: logging in using static token
[2023-03-03 18:58:04] [INFO   ] discord.client: logging in using static token
[2023-03-03 19:04:05] [INFO   ] discord.client: logging in using static token
[2023-03-03 19:04:08] [INFO   ] discord.gateway: Shard ID 0 has connected to Gateway (Session ID: 3d6281ccec3f9c0d3f34e77319bc80d9).
[2023-03-03 19:04:10] [INFO   ] bot: Ready: Uni ✨#4378 (ID: 924198727533600798)
[2023-03-04 03:11:31] [INFO   ] discord.client: logging in using static token
[2023-03-04 03:11:32] [INFO   ] discord.gateway: Shard ID 0 has connected to Gateway (Session ID: 914b3861e7d3a1209b4bedcfd6c7a8f9).
[2023-03-04 03:11:34] [INFO   ] bot: Ready: Uni ✨#4378 (ID: 924198727533600798)
[2023-03-04 05:30:15] [INFO   ] discord.client: logging in using static token
[2023-03-04 05:30:19] [INFO   ] discord.gateway: Shard ID 0 has connected to Gateway (Session ID: b2214cc060f8d3fde6b7753490094af0).
[2023-03-04 05:30:21] [INFO   ] bot: Ready: Uni ✨#4378 (ID: 924198727533600798)
[2023-03-04 05:36:10] [INFO   ] discord.client: logging in using static token
[2023-03-04 05:36:12] [INFO   ] discord.gateway: Shard ID 0 has connected to Gateway (Session ID: 1edbc8481f4e420474047419e56824e8).
[2023-03-04 05:36:14] [INFO   ] bot: Ready: Uni ✨#4378 (ID: 924198727533600798)
[2023-03-04 06:35:11] [INFO   ] discord.client: logging in using static token
[2023-03-04 06:35:17] [INFO   ] discord.gateway: Shard ID 0 has connected to Gateway (Session ID: 5d1add50a7811caa05ced95728ebe5ef).
[2023-03-04 06:35:19] [INFO   ] bot: Ready: Uni ✨#4378 (ID: 924198727533600798)
[2023-03-04 06:40:53] [INFO   ] discord.client: logging in using static token
[2023-03-04 06:40:54] [INFO   ] discord.gateway: Shard ID 0 has connected to Gateway (Session ID: d3822baa24c9d779531a01d805df9ac1).
[2023-03-04 06:40:57] [INFO   ] bot: Ready: Uni ✨#4378 (ID: 924198727533600798)
[2023-03-04 06:41:24] [ERROR  ] discord.client: Ignoring exception in on_command_error
Traceback (most recent call last):
  File "/home/runner/Uni-Python-Bot/venv/lib/python3.8/site-packages/discord/ext/commands/core.py", line 229, in wrapped
    ret = await coro(*args, **kwargs)
  File "/home/runner/Uni-Python-Bot/cogs/Information.py", line 20, in info
    embed = await Helpers(self.bot).user_info(ctx, user)
  File "/home/runner/Uni-Python-Bot/cogs/utils/helpers.py", line 52, in user_info
    embed.add_field(name=field3, value= ", ".join(reversed([r.mention for r in user.roles].remove(f"<@&{ctx.guild.id}>"))))
TypeError: 'NoneType' object is not reversible

The above exception was the direct cause of the following exception:

Traceback (most recent call last):
  File "/home/runner/Uni-Python-Bot/venv/lib/python3.8/site-packages/discord/client.py", line 409, in _run_event
    await coro(*args, **kwargs)
  File "/home/runner/Uni-Python-Bot/cogs/Listeners.py", line 40, in on_command_error
    raise error
  File "/home/runner/Uni-Python-Bot/venv/lib/python3.8/site-packages/discord/ext/commands/bot.py", line 1349, in invoke
    await ctx.command.invoke(ctx)
  File "/home/runner/Uni-Python-Bot/venv/lib/python3.8/site-packages/discord/ext/commands/core.py", line 1642, in invoke
    await ctx.invoked_subcommand.invoke(ctx)
  File "/home/runner/Uni-Python-Bot/venv/lib/python3.8/site-packages/discord/ext/commands/core.py", line 1023, in invoke
    await injected(*ctx.args, **ctx.kwargs)  # type: ignore
  File "/home/runner/Uni-Python-Bot/venv/lib/python3.8/site-packages/discord/ext/commands/core.py", line 238, in wrapped
    raise CommandInvokeError(exc) from exc
discord.ext.commands.errors.CommandInvokeError: Command raised an exception: TypeError: 'NoneType' object is not reversible
[2023-03-04 06:42:24] [INFO   ] discord.client: logging in using static token
[2023-03-04 06:42:25] [INFO   ] discord.gateway: Shard ID 0 has connected to Gateway (Session ID: 721a9572bafe1504c431d95175cd5721).
[2023-03-04 06:42:27] [INFO   ] bot: Ready: Uni ✨#4378 (ID: 924198727533600798)
[2023-03-04 06:43:42] [ERROR  ] discord.client: Ignoring exception in on_command_error
Traceback (most recent call last):
  File "/home/runner/Uni-Python-Bot/venv/lib/python3.8/site-packages/discord/client.py", line 409, in _run_event
    await coro(*args, **kwargs)
  File "/home/runner/Uni-Python-Bot/cogs/Listeners.py", line 40, in on_command_error
    raise error
  File "/home/runner/Uni-Python-Bot/venv/lib/python3.8/site-packages/discord/ext/commands/bot.py", line 1349, in invoke
    await ctx.command.invoke(ctx)
  File "/home/runner/Uni-Python-Bot/venv/lib/python3.8/site-packages/discord/ext/commands/core.py", line 1647, in invoke
    await super().invoke(ctx)
  File "/home/runner/Uni-Python-Bot/venv/lib/python3.8/site-packages/discord/ext/commands/core.py", line 1015, in invoke
    await self.prepare(ctx)
  File "/home/runner/Uni-Python-Bot/venv/lib/python3.8/site-packages/discord/ext/commands/core.py", line 932, in prepare
    await self._parse_arguments(ctx)
  File "/home/runner/Uni-Python-Bot/venv/lib/python3.8/site-packages/discord/ext/commands/core.py", line 860, in _parse_arguments
    raise TooManyArguments('Too many arguments passed to ' + self.qualified_name)
discord.ext.commands.errors.TooManyArguments: Too many arguments passed to jishaku
[2023-03-04 06:44:21] [ERROR  ] discord.client: Ignoring exception in on_command_error
Traceback (most recent call last):
  File "/home/runner/Uni-Python-Bot/venv/lib/python3.8/site-packages/discord/ext/commands/core.py", line 229, in wrapped
    ret = await coro(*args, **kwargs)
  File "/home/runner/Uni-Python-Bot/cogs/Information.py", line 24, in info
    view = Views.UserMenu(ctx, self.bot.config, util)
NameError: name 'util' is not defined

The above exception was the direct cause of the following exception:

Traceback (most recent call last):
  File "/home/runner/Uni-Python-Bot/venv/lib/python3.8/site-packages/discord/client.py", line 409, in _run_event
    await coro(*args, **kwargs)
  File "/home/runner/Uni-Python-Bot/cogs/Listeners.py", line 40, in on_command_error
    raise error
  File "/home/runner/Uni-Python-Bot/venv/lib/python3.8/site-packages/discord/ext/commands/bot.py", line 1349, in invoke
    await ctx.command.invoke(ctx)
  File "/home/runner/Uni-Python-Bot/venv/lib/python3.8/site-packages/discord/ext/commands/core.py", line 1642, in invoke
    await ctx.invoked_subcommand.invoke(ctx)
  File "/home/runner/Uni-Python-Bot/venv/lib/python3.8/site-packages/discord/ext/commands/core.py", line 1023, in invoke
    await injected(*ctx.args, **ctx.kwargs)  # type: ignore
  File "/home/runner/Uni-Python-Bot/venv/lib/python3.8/site-packages/discord/ext/commands/core.py", line 238, in wrapped
    raise CommandInvokeError(exc) from exc
discord.ext.commands.errors.CommandInvokeError: Command raised an exception: NameError: name 'util' is not defined
[2023-03-04 06:45:13] [INFO   ] discord.client: logging in using static token
[2023-03-04 06:45:15] [INFO   ] discord.gateway: Shard ID 0 has connected to Gateway (Session ID: 5cc6b4fd48658ea00748dbb86afaa121).
[2023-03-04 06:45:17] [INFO   ] bot: Ready: Uni ✨#4378 (ID: 924198727533600798)
[2023-03-04 06:46:40] [ERROR  ] discord.ui.view: Ignoring exception in view <UserMenu timeout=160.0 children=1> for item <UserSelect placeholder='views' min_values=1 max_values=1 disabled=False>
Traceback (most recent call last):
  File "/home/runner/Uni-Python-Bot/venv/lib/python3.8/site-packages/discord/ui/view.py", line 425, in _scheduled_task
    await item.callback(interaction)
  File "/home/runner/Uni-Python-Bot/util/Views.py", line 46, in select
    await self.do_something(interaction, user, msg)
  File "/home/runner/Uni-Python-Bot/cogs/Information.py", line 22, in run
    embed = await Helpers(self.bot).user_info(ctx, user)
  File "/home/runner/Uni-Python-Bot/cogs/utils/helpers.py", line 40, in user_info
    color=await self.util.image_color(user.display_avatar.url) or discord.Color.dark_embed.value
  File "/home/runner/Uni-Python-Bot/util/Middleware.py", line 75, in image_color
    return int(res["data"]["dominant"]["hex"].strip("#"), 16)
TypeError: 'NoneType' object is not subscriptable
[2023-03-04 06:47:33] [INFO   ] discord.client: logging in using static token
[2023-03-04 06:47:35] [INFO   ] discord.gateway: Shard ID 0 has connected to Gateway (Session ID: 4402ec9f7702385ebc8ce07e4f130425).
[2023-03-04 06:47:37] [INFO   ] bot: Ready: Uni ✨#4378 (ID: 924198727533600798)
[2023-03-04 06:49:13] [INFO   ] discord.client: logging in using static token
[2023-03-04 06:49:14] [INFO   ] discord.gateway: Shard ID 0 has connected to Gateway (Session ID: 83df823a41c246e2d1439fe4722324db).
[2023-03-04 06:49:17] [INFO   ] bot: Ready: Uni ✨#4378 (ID: 924198727533600798)
[2023-03-04 06:51:33] [INFO   ] discord.client: logging in using static token
[2023-03-04 06:51:35] [INFO   ] discord.gateway: Shard ID 0 has connected to Gateway (Session ID: 276fab46d6bf0f56285f6b699dabc98b).
[2023-03-04 06:51:37] [INFO   ] bot: Ready: Uni ✨#4378 (ID: 924198727533600798)
[2023-03-04 06:54:14] [ERROR  ] discord.ui.view: Ignoring exception in view <UserMenu timeout=160.0 children=1> for item <UserSelect placeholder='views' min_values=1 max_values=1 disabled=False>
Traceback (most recent call last):
  File "/home/runner/Uni-Python-Bot/venv/lib/python3.8/site-packages/discord/ui/view.py", line 425, in _scheduled_task
    await item.callback(interaction)
  File "/home/runner/Uni-Python-Bot/util/Views.py", line 46, in select
    await self.do_something(interaction, user, msg)
  File "/home/runner/Uni-Python-Bot/cogs/Information.py", line 22, in run
    embed = await Helpers(self.bot).user_info(ctx, user)
  File "/home/runner/Uni-Python-Bot/cogs/utils/helpers.py", line 40, in user_info
    color=await self.util.image_color(user.display_avatar.url)
  File "/home/runner/Uni-Python-Bot/util/Middleware.py", line 78, in image_color
    return discord.Color.dark_embed().value
AttributeError: type object 'Colour' has no attribute 'dark_embed'
[2023-03-04 07:00:27] [INFO   ] discord.client: logging in using static token
[2023-03-04 07:00:28] [INFO   ] discord.gateway: Shard ID 0 has connected to Gateway (Session ID: 830218ffde9ecf6b5bd40c76d227d785).
[2023-03-04 07:00:30] [INFO   ] bot: Ready: Uni ✨#4378 (ID: 924198727533600798)
[2023-03-04 07:03:00] [ERROR  ] discord.ui.view: Ignoring exception in view <UserMenu timeout=160.0 children=1> for item <UserSelect placeholder='views' min_values=1 max_values=1 disabled=False>
Traceback (most recent call last):
  File "/home/runner/Uni-Python-Bot/venv/lib/python3.8/site-packages/discord/ui/view.py", line 425, in _scheduled_task
    await item.callback(interaction)
  File "/home/runner/Uni-Python-Bot/util/Views.py", line 46, in select
    await self.do_something(interaction, user, msg)
  File "/home/runner/Uni-Python-Bot/cogs/Information.py", line 22, in run
    embed = await Helpers(self.bot).user_info(ctx, user)
  File "/home/runner/Uni-Python-Bot/cogs/utils/helpers.py", line 40, in user_info
    color=await self.util.image_color(user.display_avatar.url)
  File "/home/runner/Uni-Python-Bot/util/Middleware.py", line 78, in image_color
    return discord.Color.dark_embed().value
AttributeError: type object 'Colour' has no attribute 'dark_embed'
[2023-03-04 07:05:56] [INFO   ] discord.client: logging in using static token
[2023-03-04 07:05:57] [INFO   ] discord.gateway: Shard ID 0 has connected to Gateway (Session ID: b477abade4653c1137e8b56e26bcdbfa).
[2023-03-04 07:05:59] [INFO   ] bot: Ready: Uni ✨#4378 (ID: 924198727533600798)
[2023-03-04 07:07:25] [INFO   ] discord.client: logging in using static token
[2023-03-04 07:07:26] [INFO   ] discord.gateway: Shard ID 0 has connected to Gateway (Session ID: 4f3de997a7435d165edbb59a72bddbdf).
[2023-03-04 07:07:29] [INFO   ] bot: Ready: Uni ✨#4378 (ID: 924198727533600798)
[2023-03-04 17:46:04] [INFO   ] discord.client: logging in using static token
[2023-03-04 17:46:05] [INFO   ] discord.gateway: Shard ID 0 has connected to Gateway (Session ID: 2fa2a26c1c650722193fbb5fb6990d8b).
[2023-03-04 17:46:08] [INFO   ] bot: Ready: Uni ✨#4378 (ID: 924198727533600798)
[2023-03-04 17:48:36] [INFO   ] discord.client: logging in using static token
[2023-03-04 17:48:37] [INFO   ] discord.gateway: Shard ID 0 has connected to Gateway (Session ID: 166dc10c1e9b9201d44b9584600425e7).
[2023-03-04 17:48:39] [INFO   ] bot: Ready: Uni ✨#4378 (ID: 924198727533600798)
[2023-03-04 17:51:40] [INFO   ] discord.client: logging in using static token
[2023-03-04 17:51:41] [INFO   ] discord.gateway: Shard ID 0 has connected to Gateway (Session ID: 3a1cc2432439a3fef1ad925cf891b06b).
[2023-03-04 17:51:43] [INFO   ] bot: Ready: Uni ✨#4378 (ID: 924198727533600798)
[2023-03-04 17:57:50] [INFO   ] discord.client: logging in using static token
[2023-03-04 17:57:52] [INFO   ] discord.gateway: Shard ID 0 has connected to Gateway (Session ID: 0c0a23c093456067b5e7e8da6bf1e00a).
[2023-03-04 17:57:54] [INFO   ] bot: Ready: Uni ✨#4378 (ID: 924198727533600798)
[2023-03-04 18:09:20] [INFO   ] discord.client: logging in using static token
[2023-03-04 18:10:13] [INFO   ] discord.client: logging in using static token
[2023-03-04 18:11:24] [INFO   ] discord.client: logging in using static token
[2023-03-04 18:11:25] [INFO   ] discord.gateway: Shard ID 0 has connected to Gateway (Session ID: 10b1e3316f0a970bfc4efffa6243a2e0).
[2023-03-04 18:11:28] [INFO   ] bot: Ready: Uni ✨#4378 (ID: 924198727533600798)
[2023-03-04 18:12:07] [INFO   ] discord.client: logging in using static token
[2023-03-04 18:12:08] [INFO   ] discord.gateway: Shard ID 0 has connected to Gateway (Session ID: 6c177639881b5484be1a0614e1364c4c).
[2023-03-04 18:12:10] [INFO   ] bot: Ready: Uni ✨#4378 (ID: 924198727533600798)
[2023-03-04 18:12:20] [ERROR  ] discord.client: Ignoring exception in on_ready
Traceback (most recent call last):
  File "/home/runner/Uni-Python-Bot/venv/lib/python3.8/site-packages/discord/client.py", line 409, in _run_event
    await coro(*args, **kwargs)
  File "/home/runner/Uni-Python-Bot/cogs/Listeners.py", line 15, in on_ready
    await Locales.fetch_langs(self.bot)
  File "/home/runner/Uni-Python-Bot/util/Locales.py", line 35, in fetch_langs
    langs_cache[str(guild.id)]["lang"] = lang
KeyError: '769787403854282802'
[2023-03-04 19:15:51] [INFO   ] discord.client: logging in using static token
[2023-03-04 19:15:53] [INFO   ] discord.gateway: Shard ID 0 has connected to Gateway (Session ID: 0f28aa9c4822d7952a1858c652ca0abf).
[2023-03-04 19:15:55] [INFO   ] bot: Ready: Uni ✨#4378 (ID: 924198727533600798)
[2023-03-04 20:17:04] [INFO   ] discord.client: logging in using static token
[2023-03-04 20:17:06] [INFO   ] discord.gateway: Shard ID 0 has connected to Gateway (Session ID: 6e4fa7684932aa8cd17c33ec9395c029).
[2023-03-04 20:17:08] [INFO   ] bot: Ready: Uni ✨#4378 (ID: 924198727533600798)
[2023-03-05 06:57:26] [INFO   ] discord.client: logging in using static token
[2023-03-05 06:57:27] [INFO   ] discord.gateway: Shard ID 0 has connected to Gateway (Session ID: cd12df1ed51fd52e109ea76591f9e5c6).
[2023-03-05 06:57:30] [INFO   ] bot: Ready: Uni ✨#4378 (ID: 924198727533600798)
